Workbook

Sheet Cost Model
A1: CALIBER · LICENSING COST MODEL
A2: Editable model - change the highlighted (amber) input cells and every total recalculates. Benchmark-based estimate for planning, not a VIFM price quote.
A4: HEADLINE - 3,000 EMPLOYEES, ALL 12 SERVICES
B5: Shared cloud | C5: Sovereign
A6: Annual recurring | B6: =B52 | C6: =C52
A7: Year 1 (incl. one-time) | B7: =B53 | C7: =C53
A8: 3-year total (TCO) | B8: =B54 | C8: =C54
A9: Price / employee / year | B9: =B55 | C9: =C55
A11: INPUTS - edit the amber cells
A12: Employees | B12: 3000
A13: Deployment tier | B13: Shared cloud
A14: Bundle discount % (all-access vs a-la-carte) | B14: 0.63
A15: Support & SLA (% of licence) | B15: 0.12
A16: One-time implementation / professional services | B16: 110000
A17: Sovereign one-time setup (dedicated instance) | B17: 90000
A18: Sovereign annual uplift (instance + SLA) | B18: 90000
A19: Term for TCO (years) | B19: 3
A20: Multi-year discount (years 2+) | B20: 0
A21: FX rate (USD -> display currency) | B21: 1 | C21: USD | D21: set rate: SAR 3.75 / AED 3.67
A23: SERVICE ENGINE - annual volumes scale with headcount; edit any volume or unit price
A24: Service | B24: Basis | C24: Annual volume | D24: Unit price (USD) | E24: A-la-carte (USD)
A25: Persona (behavioural self-report) | B25: ~per employee | C25: =ROUND($B$12*0.8333,0) | D25: 30 | E25: =C25*D25
A26: Logica (cognitive ability) | B26: selective | C26: =ROUND($B$12*0.5,0) | D26: 30 | E26: =C26*D26
A27: Psychometrics (cognitive + personality) | B27: selective | C27: =ROUND($B$12*0.5,0) | D27: 30 | E27: =C27*D27
A28: Fluent (English / CEFR) | B28: selective | C28: =ROUND($B$12*0.4,0) | D28: 40 | E28: =C28*D28
A29: Techno (technical certification) | B29: technical roles | C29: =ROUND($B$12*0.4,0) | D29: 90 | E29: =C29*D29
A30: Pre-Hire (screening) | B30: hiring volume | C30: =ROUND($B$12*0.3,0) | D30: 60 | E30: =C30*D30
A31: Assessment Center (full AC) | B31: leaders / HiPo | C31: =ROUND($B$12*0.0667,0) | D31: 600 | E31: =C31*D31
A32: Reflect 360 | B32: leaders | C32: =ROUND($B$12*0.0833,0) | D32: 180 | E32: =C32*D32
A33: AI Readiness Compass (org) | B33: per business unit | C33: =ROUND($B$12/300,0) | D33: 6000 | E33: =C33*D33
A34: Personal AI snapshot | B34: selective | C34: =ROUND($B$12*0.5,0) | D34: 10 | E34: =C34*D34
A35: Academy (course completions) | B35: workforce | C35: =ROUND($B$12*1,0) | D35: 35 | E35: =C35*D35
A36: Credentials (issued) | B36: outcomes | C36: =ROUND($B$12*1.3333,0) | D36: 8 | E36: =C36*D36
A37: Role Readiness (bespoke) | B37: succession / role moves | C37: =ROUND($B$12*0.1,0) | D37: 120 | E37: =C37*D37
A38: A-la-carte total (retail, before bundling) | E38: =SUM(E25:E37)
A40: OUTPUTS - selected tier (see Deployment tier above)
A41: Annual licence (platform + all-access usage) | B41: =E38*(1-$B$14)
A42: Annual support & SLA | B42: =B41*$B$15
A43: Sovereign annual uplift | B43: =IF($B$13="Sovereign",$B$18,0)
A44: Annual recurring total | B44: =B41+B42+B43
...

Sheet Notes & Assumptions
A1: CALIBER LICENSING COST MODEL - NOTES & ASSUMPTIONS
A3: Purpose
A4: A planning model for pricing a Caliber platform licence to a client organisation that uses all 12 services. It is benchmark-based, not a VIFM price list (the platform has no published prices). Final pricing depends on VIFM strategy, margin target, region and the specific deal.
A6: How it works
A7: 1) The SERVICE ENGINE estimates realistic annual volumes per service (scaled from headcount) x a unit price = an a-la-carte 'retail' value of the suite.
A8: 2) A BUNDLE DISCOUNT converts that retail value into the committed annual all-access licence (the discount reflects both volume commitment and the reality that not everyone uses every service).
A9: 3) Support & SLA is added as a % of the licence. One-time professional services (onboarding, configuration, content/framework setup, training) are added in Year 1.
A10: 4) The SOVEREIGN tier adds a one-time setup (dedicated in-country instance) and an annual instance/ops + sovereign-SLA uplift.
A12: Default assumptions (all editable)
A13: - 3,000 employees, all 12 services enabled, active adoption.
A14: - Bundle discount 63%, support 12% of licence, one-time PS USD 110,000.
A15: - Sovereign: +USD 90,000 one-time setup and +USD 90,000 / year.
... A26: Per-unit prices are illustrative GCC enterprise mid-points. They are not VIFM's rate card. Treat every figure as a starting anchor for a commercial conversation.

Sheet Operating Cost & Margin
A1: OPERATING COST & MARGIN - per 3,000-member client
A2: Fixed cost does NOT move with usage; variable cost scales with the capacity slider. Claude figures are grounded in the platform's real per-assessment call counts and max_tokens.
A4: HEADLINE
B5: Fixed (annual) | C5: Variable (@ capacity) | D5: Total operating | E5: Margin
B6: =B47 | C6: =B48 | D6: =B49 | E6: =B56
A8: INPUTS - edit the amber cells
A9: Capacity / adoption % (share of full-adoption volumes) | B9: 0.5
A10: Claude input price (USD / M tokens) | B10: 3
A11: Claude output price (USD / M tokens) | B11: 15
A12: Incremental infra per assessment (storage / bandwidth / PDF) | B12: 0.05
A13: Speech per speaking test (0 = browser default / free) | B13: 0
A14: One-off / setup AI per year (course import, ARC reg, JD, Reflect setup) | B14: 2500
A15: Deployment tier (from Cost Model) | B15: ='Cost Model'!B13
A17: VARIABLE - Claude API by service (model: claude-sonnet-4-5; $/unit = calls x tokens x price)
A18: Service | B18: Eff. volume | C18: Calls/unit | D18: In tok | E18: Out tok | F18: $/unit | G18: Annual $
A19: Persona (report narrative) | B19: ='Cost Model'!C25*$B$9 | C19: 3 | D19: 2000 | E19: 1500 | F19: =C19*(D19/1000000*$B$10+E19/1000000*$B$11) | G19: =B19*F19
A20: Logica (cognitive) | B20: ='Cost Model'!C26*$B$9 | C20: 0.5 | D20: 600 | E20: 2200 | F20: =C20*(D20/1000000*$B$10+E20/1000000*$B$11) | G20: =B20*F20
A21: Psychometrics | B21: ='Cost Model'!C27*$B$9 | C21: 0.3 | D21: 600 | E21: 2200 | F21: =C21*(D21/1000000*$B$10+E21/1000000*$B$11) | G21: =B21*F21
A22: Fluent (gen + writing + speaking) | B22: ='Cost Model'!C28*$B$9 | C22: 3 | D22: 1100 | E22: 1300 | F22: =C22*(D22/1000000*$B$10+E22/1000000*$B$11) | G22: =B22*F22
A23: Techno (indicative gen; bank = 0) | B23: ='Cost Model'!C29*$B$9 | C23: 0.6 | D23: 600 | E23: 2200 | F23: =C23*(D23/1000000*$B$10+E23/1000000*$B$11) | G23: =B23*F23
A24: Pre-Hire (quiz + Fluent + CBI) | B24: ='Cost Model'!C30*$B$9 | C24: 10 | D24: 1100 | E24: 1300 | F24: =C24*(D24/1000000*$B$10+E24/1000000*$B$11) | G24: =B24*F24
A25: Assessment Center (report AI not wired) | B25: ='Cost Model'!C31*$B$9 | C25: 0 | D25: 0 | E25: 0 | F25: =C25*(D25/1000000*$B$10+E25/1000000*$B$11) | G25: =B25*F25
A26: Reflect 360 (tips) | B26: ='Cost Model'!C32*$B$9 | C26: 1 | D26: 700 | E26: 2000 | F26: =C26*(D26/1000000*$B$10+E26/1000000*$B$11) | G26: =B26*F26
A27: AI Readiness Compass (pathway) | B27: ='Cost Model'!C33*$B$9 | C27: 1 | D27: 2000 | E27: 2000 | F27: =C27*(D27/1000000*$B$10+E27/1000000*$B$11) | G27: =B27*F27
A28: Personal AI snapshot | B28: ='Cost Model'!C34*$B$9 | C28: 1 | D28: 2000 | E28: 1500 | F28: =C28*(D28/1000000*$B$10+E28/1000000*$B$11) | G28: =B28*F28
A29: Academy (~3 lesson checks) | B29: ='Cost Model'!C35*$B$9 | C29: 3 | D29: 1200 | E29: 2500 | F29: =C29*(D29/1000000*$B$10+E29/1000000*$B$11) | G29: =B29*F29
A30: Credentials (no AI) | B30: ='Cost Model'!C36*$B$9 | C30: 0 | D30: 0 | E30: 0 | F30: =C30*(D30/1000000*$B$10+E30/1000000*$B$11) | G30: =B30*F30
A31: Role Readiness | B31: ='Cost Model'!C37*$B$9 | C31: 1 | D31: 600 | E31: 2200 | F31: =C31*(D31/1000000*$B$10+E31/1000000*$B$11) | G31: =B31*F31
A32: Claude API total (annual, at capacity) | G32: =SUM(G19:G31)
A33: Speech transcription (Fluent + Pre-Hire speaking) | G33: =('Cost Model'!C28+'Cost Model'!C30)*$B$9*$B$13
A34: Incremental infra (all assessments) | G34: =SUM(B19:B31)*$B$12
A35: One-off / setup AI (annual) | G35: =$B$14
A36: VARIABLE TOTAL (annual, at capacity) | G36: =G32+G33+G34+G35
A38: FIXED COSTS (annual - do not scale with usage)
A39: Hosting / infra (Supabase + Render, allocated) | B39: 12000
A40: Support + customer success (allocated) | B40: 45000
A41: Content / framework upkeep + platform eng | B41: 25000
A42: Email (MS Graph) + misc SaaS | B42: 3500
A43: Sovereign instance ops + compliance (if sovereign) | B43: =IF('Cost Model'!B13="Sovereign",40000,0)
A44: FIXED TOTAL (annual) | B44: =SUM(B39:B43)
...

Sheet Portfolio (10 clients)
A1: PORTFOLIO ECONOMICS - Caliber licensing at scale
A2: Realistic plan: 10 clients in 12 months (each ~3,000 members). Company fixed is right-sized for a lean ~10-client operation - it steps up as you scale past ~25. Revenue and per-client variable pull live from the other tabs.
A4: HEADLINE
B5: Clients | C5: Annual revenue | D5: Total cost | E5: Gross profit | F5: Margin
B6: =B9 | C6: =B32 | D6: =B35 | E6: =B36 | F6: =B37
A8: INPUTS - edit the amber cells
A9: Number of clients | B9: 10
A10: % of clients on Sovereign tier | B10: 0.2
A11: Revenue / client - Shared (from Cost Model) | B11: ='Cost Model'!B52
A12: Revenue / client - Sovereign (from Cost Model) | B12: ='Cost Model'!C52
A13: Blended revenue / client | B13: =(1-B10)*B11+B10*B12
A14: Per-client variable / yr (from Operating tab, at capacity) | B14: ='Operating Cost & Margin'!G36
A15: One-time onboarding / client (from Cost Model) | B15: ='Cost Model'!B16
A17: COMPANY-LEVEL FIXED (shared across ALL clients, annual)
A18: Platform engineering (lean team / fractional) | B18: 350000
A19: Content / framework upkeep (mostly built) | B19: 120000
A20: Central infra / control plane / security | B20: 45000
A21: G&A + sales & marketing (relationship sales) | B21: 200000
A22: COMPANY FIXED TOTAL | B22: =SUM(B18:B21)
A24: PER-CLIENT COST (annual)
A25: Support + customer success / client | B25: 15000
A26: Infra / client (blended shared vs sovereign) | B26: =(1-B10)*3000+B10*25000
A27: Variable / client (API + infra + setup) | B27: =B14
A28: PER-CLIENT COST TOTAL | B28: =SUM(B25:B27)
A29: x number of clients = client-level cost | B29: =B28*B9
A31: PORTFOLIO P&L (annual, steady state)
A32: Annual revenue | B32: =B9*B13
A33: Company fixed | B33: =B22
A34: Client-level cost | B34: =B29
A35: Total cost | B35: =B33+B34
A36: Gross profit | B36: =B32-B35
A37: Gross margin | B37: =B36/B32
A38: Revenue / client | B38: =B13
A39: Fully-loaded cost / client | B39: =B35/B9
A40: Profit / client | B40: =B36/B9
A41: Year-1 onboarding (one-time, all clients) | B41: =B9*B15
A43: OPERATING LEVERAGE - margin grows as company fixed amortizes
A44: Clients | B44: 3 | C44: 5 | D44: 10 | E44: 15 | F44: 25
A45: Annual revenue | B45: =B44*$B$13 | C45: =C44*$B$13 | D45: =D44*$B$13 | E45: =E44*$B$13 | F45: =F44*$B$13
A46: Total cost | B46: =$B$22+B44*$B$28 | C46: =$B$22+C44*$B$28 | D46: =$B$22+D44*$B$28 | E46: =$B$22+E44*$B$28 | F46: =$B$22+F44*$B$28
...

Sheet Year-1 Cash View
A1: YEAR-1 CASH VIEW - 10-client ramp
A2: Month-by-month cash as clients sign through the year, against operating cost + the one-time platform-hardening spend. Edit the amber rows (new clients/month, hardening/month).
A4: ASSUMPTIONS (pulled from other tabs; amber = editable)
A5: Blended revenue / client / yr | B5: ='Portfolio (10 clients)'!B13
A6: Onboarding fee / client (one-time) | B6: ='Cost Model'!B16
A7: Per-client operating cost / yr | B7: ='Portfolio (10 clients)'!B28
A8: Company fixed / yr | B8: ='Portfolio (10 clients)'!B22
A9: Onboarding delivery cost (% of fee) | B9: 0.4
A11: MONTH-BY-MONTH (USD)
B12: M1 | C12: M2 | D12: M3 | E12: M4 | F12: M5 | G12: M6 | H12: M7 | I12: M8 | J12: M9 | K12: M10 | L12: M11 | M12: M12 | N12: FY total
A13: New clients signed | B13: 1 | C13: 1 | D13: 1 | E13: 1 | F13: 1 | G13: 1 | H13: 1 | I13: 1 | J13: 1 | K13: 1 | L13: 0 | M13: 0 | N13: =SUM(B13:M13)
A14: Cumulative clients | B14: =B13 | C14: =B14+C13 | D14: =C14+D13 | E14: =D14+E13 | F14: =E14+F13 | G14: =F14+G13 | H14: =G14+H13 | I14: =H14+I13 | J14: =I14+J13 | ... M14: =L14+M13 | N14: =M14
A15: Recurring revenue | B15: =B14*$B$5/12 | C15: =C14*$B$5/12 | D15: =D14*$B$5/12 | E15: =E14*$B$5/12 | F15: =F14*$B$5/12 | G15: =G14*$B$5/12 | H15: =H14*$B$5/12 | I15: =I14*$B$5/12 | ... M15: =M14*$B$5/12 | N15: =SUM(B15:M15)
A16: Onboarding fees (one-time) | B16: =B13*$B$6 | C16: =C13*$B$6 | D16: =D13*$B$6 | E16: =E13*$B$6 | F16: =F13*$B$6 | G16: =G13*$B$6 | H16: =H13*$B$6 | I16: =I13*$B$6 | ... M16: =M13*$B$6 | N16: =SUM(B16:M16)
A17: Total revenue | B17: =B15+B16 | C17: =C15+C16 | D17: =D15+D16 | E17: =E15+E16 | F17: =F15+F16 | G17: =G15+G16 | H17: =H15+H16 | I17: =I15+I16 | ... M17: =M15+M16 | N17: =SUM(B17:M17)
A18: Company fixed (1/12) | B18: =$B$8/12 | C18: =$B$8/12 | D18: =$B$8/12 | E18: =$B$8/12 | F18: =$B$8/12 | G18: =$B$8/12 | H18: =$B$8/12 | I18: =$B$8/12 | ... M18: =$B$8/12 | N18: =SUM(B18:M18)
A19: Per-client operating | B19: =B14*$B$7/12 | C19: =C14*$B$7/12 | D19: =D14*$B$7/12 | E19: =E14*$B$7/12 | F19: =F14*$B$7/12 | G19: =G14*$B$7/12 | H19: =H14*$B$7/12 | I19: =I14*$B$7/12 | ... M19: =M14*$B$7/12 | N19: =SUM(B19:M19)
A20: Platform hardening (one-time) | B20: 100000 | C20: 100000 | D20: 100000 | E20: 100000 | F20: 0 | G20: 0 | H20: 0 | I20: 0 | J20: 0 | K20: 0 | L20: 0 | M20: 0 | N20: =SUM(B20:M20)
A21: Onboarding delivery | B21: =B13*$B$6*$B$9 | C21: =C13*$B$6*$B$9 | D21: =D13*$B$6*$B$9 | E21: =E13*$B$6*$B$9 | F21: =F13*$B$6*$B$9 | G21: =G13*$B$6*$B$9 | H21: =H13*$B$6*$B$9 | I21: =I13*$B$6*$B$9 | ... M21: =M13*$B$6*$B$9 | N21: =SUM(B21:M21)
A22: Total cost | B22: =B18+B19+B20+B21 | C22: =C18+C19+C20+C21 | D22: =D18+D19+D20+D21 | E22: =E18+E19+E20+E21 | F22: =F18+F19+F20+F21 | G22: =G18+G19+G20+G21 | H22: =H18+H19+H20+H21 | I22: =I18+I19+I20+I21 | ... M22: =M18+M19+M20+M21 | N22: =SUM(B22:M22)
A23: Net cash (month) | B23: =B17-B22 | C23: =C17-C22 | D23: =D17-D22 | E23: =E17-E22 | F23: =F17-F22 | G23: =G17-G22 | H23: =H17-H22 | I23: =I17-I22 | ... M23: =M17-M22 | N23: =SUM(B23:M23)
A24: Cumulative cash | B24: =B23 | C24: =B24+C23 | D24: =C24+D23 | E24: =D24+E23 | F24: =E24+F23 | G24: =F24+G23 | H24: =G24+H23 | I24: =H24+I23 | J24: =I24+J23 | ... M24: =L24+M23 | N24: =M24
A26: Read: Year-1 ends cash-positive even after the hardening spend - onboarding fees + ramping recurring outpace it. The Cumulative cash row shows the funding dip (max drawdown) before it turns positive; that dip is the working capital needed up front.

Sheet Engineering Roadmap
A1: ENGINEERING ROADMAP - 10 clients in 12 months
A2: The hardening that makes Caliber a solid, load-test-proven portal for 10 clients. ~6-10 weeks of core work; client onboarding runs in parallel. Edit Status / Owner (amber).
A4: When | B4: Workstream | C4: What it fixes | D4: Effort | E4: Status | F4: Owner
A5: Q1 | B5: Job queue + workers (AI gen/scoring, PDF, vision -> async) | C5: Removes 4 of 5 critical bottlenecks; frees the event loop | D5: 3-4 wks | E5: Not started
A6: Q1 | B6: Puppeteer browser pool + PDF caching | C6: Chromium OOM under concurrent PDFs | D6: 1-2 wks | E6: Not started
A7: Q1-Q2 | B7: DB connection pooling (Supavisor) + batch N+1 + indexes | C7: Connection exhaustion at concurrency | D7: 2 wks | E7: Not started
A8: Q2 | B8: Autoscale 2-4 web + 2 workers, health checks, CI/CD | C8: Single instance + manual deploy | D8: 1-2 wks | E8: Not started
A9: Q2 | B9: Monitoring + SLOs (Sentry / Datadog) | C9: No observability today | D9: 1 wk | E9: Not started
A10: GATE | B10: GATE: load test to a measured ceiling (before client 6) | C10: Converts estimates into a contractable SLA | D10: milestone | E10: Not started
A11: Q3 | B11: Retention crons (proctor snapshots, ARA materials) | C11: Unbounded storage growth | D11: 1 wk | E11: Not started
A12: Q3 | B12: Dedicated instance for the sovereign client | C12: Data residency / compliance | D12: 1 wk | E12: Not started
A13: Q3 | B13: Anthropic: higher tier + concurrency queue | C13: Shared rate-limit ceiling | D13: 0.5 wk | E13: Not started
A14: Q4 | B14: DR: backups + failover + runbook | C14: Resilience / SLA | D14: 1-2 wks | E14: Not started
A16: NOT NEEDED FOR 10 CLIENTS (defer until >25 clients or data-residency demand)
A17: defer | B17: Tenant sharding / multi-instance fleet | C17: Only beyond ~25 clients
A18: defer | B18: Per-tenant API keys | C18: Single key + queue suffices at 10
A19: defer | B19: Read replicas | C19: Not needed at this concurrency
